Workbook
Name Slicer_Category: #N/A
Name Slicer_Parking?: #N/A
Name top.or.bottom: Pivot!$M$90

Sheet mockup

Sheet Pivot
A1: Date (Year) | B1: Date (Month) | C1: Sum of Amount | D1: Sum of Quantity | E1: Count of Cust ID | F1: Distinct Count of Cust ID2 | I1: Amount | J1: Quantity | K1: Orders | L1: Customers
A2: 2017 | B2: May | C2: 84870.35 | D2: 18397 | E2: 2145 | F2: 345 | H2: Now | I2: =C14 -> 81789.35 | J2: =D14 -> 17247 | K2: =E14 -> 2087 | L2: =F14 -> 345
A3: 2017 | B3: Jun | C3: 73911.85 | D3: 17079 | E3: 2017 | F3: 346 | H3: Then | I3: =C2 -> 84870.35 | J3: =D2 -> 18397 | K3: =E2 -> 2145 | L3: =F2 -> 345
A4: 2017 | B4: Jul | C4: 77529.3 | D4: 17507 | E4: 2152 | F4: 346 | H4: Variance | I4: =I2/I3-1 -> -0.036302431 | J4: =J2/J3-1 -> -0.062510192 | K4: =K2/K3-1 -> -0.027039627 | L4: =L2/L3-1 -> 0
A5: 2017 | B5: Aug | C5: 77368.6 | D5: 17227 | E5: 2063 | F5: 346 | H5: Trend
A6: 2017 | B6: Sep | C6: 78427.8 | D6: 17407 | E6: 2058 | F6: 346
A7: 2017 | B7: Oct | C7: 81189.55 | D7: 17050 | E7: 2087 | F7: 345
A8: 2017 | B8: Nov | C8: 77563.65 | D8: 17172 | E8: 2059 | F8: 345 | H8: Now | I8: =B14&"-"&A14 -> May-2018
A9: 2017 | B9: Dec | C9: 78875.75 | D9: 17171 | E9: 2102 | F9: 346 | H9: Year Ago | I9: =B2&"-"&A2 -> May-2017
A10: 2018 | B10: Jan | C10: 83231.95 | D10: 17733 | E10: 2103 | F10: 346
A11: 2018 | B11: Feb | C11: 79708.4 | D11: 17478 | E11: 1999 | F11: 346
A12: 2018 | B12: Mar | C12: 83686.5 | D12: 18166 | E12: 2210 | F12: 347
A13: 2018 | B13: Apr | C13: 71926.65 | D13: 16087 | E13: 2025 | F13: 346
A14: 2018 | B14: May | C14: 81789.35 | D14: 17247 | E14: 2087 | F14: 345
A15: Grand Total | C15: 1030079.7 | D15: 225721 | E15: 27107 | F15: 347
A42: Sum of Amount | B42: Column Labels
B43: 2017 | J43: 2018
A44: Row Labels | B44: May | C44: Jun | D44: Jul | E44: Aug | F44: Sep | G44: Oct | H44: Nov | I44: Dec | J44: Jan | K44: Feb | L44: Mar | M44: Apr | N44: May | R44: Store | S44: Now | T44: Then | U44: % Var | V44: Trend
A45: Ballarat | B45: 14012.65 | C45: 9676.75 | D45: 10989 | E45: 9762.65 | F45: 10535 | G45: 11320.3 | H45: 9950.1 | I45: 9293.45 | J45: 10102 | K45: 10794.95 | L45: 12214.4 | M45: 10565.2 | N45: 13829.4 | R45: =A45 -> Ballarat | S45: =N45 -> 13829.4 | T45: =B45 -> 14012.65 | U45: =S45/T45-1 -> -0.013077469
A46: Geelong | B46: 9522.4 | C46: 10287.4 | D46: 9305.95 | E46: 10976.75 | F46: 14015.05 | G46: 13684.9 | H46: 9677.6 | I46: 11461.75 | J46: 14897.15 | K46: 10265.65 | L46: 9929.85 | M46: 10641.75 | N46: 13314 | R46: =A46 -> Geelong | S46: =N46 -> 13314 | T46: =B46 -> 9522.4 | U46: =S46/T46-1 -> 0.39817693
A47: Bendigo | B47: 10791.8 | C47: 8518.95 | D47: 12931.55 | E47: 10051.65 | F47: 12118.65 | G47: 9532 | H47: 9639.35 | I47: 12202.3 | J47: 12027.85 | K47: 10919.25 | L47: 10518.5 | M47: 10063.7 | N47: 13249.5 | R47: =A47 -> Bendigo | S47: =N47 -> 13249.5 | T47: =B47 -> 10791.8 | U47: =S47/T47-1 -> 0.22773773
A48: Mackay | B48: 12547.85 | C48: 9287.25 | D48: 11904 | E48: 8899.3 | F48: 9581.2 | G48: 13219.3 | H48: 10786.25 | I48: 12751.25 | J48: 10087.15 | K48: 11082.75 | L48: 11808.4 | M48: 9690.35 | N48: 11588.95 | R48: =A48 -> Mackay | S48: =N48 -> 11588.95 | T48: =B48 -> 12547.85 | U48: =S48/T48-1 -> -0.076419466
A49: Cairns | B49: 13225.5 | C49: 10359.2 | D49: 12362.05 | E49: 12315.35 | F49: 10461.8 | G49: 12451.45 | H49: 11271.6 | I49: 11243.95 | J49: 12625.55 | K49: 11031.85 | L49: 11087.65 | M49: 11051.65 | N49: 11284.45 | R49: =A49 -> Cairns | S49: =N49 -> 11284.45 | T49: =B49 -> 13225.5 | U49: =S49/T49-1 -> -0.14676572
A50: Townsville | B50: 11301.7 | C50: 10764.4 | D50: 9548.45 | E50: 11391.75 | F50: 10754.4 | G50: 13473.7 | H50: 10879.85 | I50: 12492.1 | J50: 9773 | K50: 13724 | L50: 10676.35 | M50: 8420.45 | N50: 11233.65 | R50: =A50 -> Townsville | S50: =N50 -> 11233.65 | T50: =B50 -> 11301.7 | U50: =S50/T50-1 -> -0.006021218
A51: Gold Coast | B51: 9190.8 | C51: 11648.75 | D51: 11180.05 | E51: 9824 | F51: 11235.65 | G51: 12240.95 | H51: 11102.65 | I51: 10068.2 | J51: 9906.1 | K51: 11210.7 | L51: 11279.3 | M51: 9958.7 | N51: 11135.3 | R51: =A51 -> Gold Coast | S51: =N51 -> 11135.3 | T51: =B51 -> 9190.8 | U51: =S51/T51-1 -> 0.21157027
A52: Newcastle | B52: 12080.35 | C52: 9846.95 | D52: 10687.8 | E52: 11881 | F52: 10952.85 | G52: 9358.65 | H52: 10392.8 | I52: 12372.25 | J52: 9548.7 | K52: 10162.3 | L52: 13924.85 | M52: 11378.2 | N52: 10860.8 | R52: =A52 -> Newcastle | S52: =N52 -> 10860.8 | T52: =B52 -> 12080.35 | U52: =S52/T52-1 -> -0.1009532
A53: Wollongong | B53: 12314.8 | C53: 12523.7 | D53: 12080.2 | E53: 8827.15 | F53: 11254.65 | G53: 10422.6 | H53: 11680.9 | I53: 10105 | J53: 11665 | K53: 12125.5 | L53: 13172.45 | M53: 9433.2 | N53: 10736.85 | R53: =A53 -> Wollongong | S53: =N53 -> 10736.85 | T53: =B53 -> 12314.8 | U53: =S53/T53-1 -> -0.12813444
A54: Rockhampton | B54: 14716.4 | C54: 11007.65 | D54: 12883.8 | E54: 11482.1 | F54: 10547.3 | G54: 11157.45 | H54: 13364.55 | I54: 11596.95 | J54: 11635.85 | K54: 13484.85 | L54: 11856.25 | M54: 8598 | N54: 10687 | R54: =A54 -> Rockhampton | S54: =N54 -> 10687 | T54: =B54 -> 14716.4 | U54: =S54/T54-1 -> -0.27380338
A55: Central Coast | B55: 12412.95 | C55: 10453.45 | D55: 12555.85 | E55: 12213.95 | F55: 10454.05 | G55: 10477.95 | H55: 13710.8 | I55: 11907.25 | J55: 14620.55 | K55: 11604.15 | L55: 12680.95 | M55: 10436.2 | N55: 10530.2 | R55: =A55 -> Central Coast | S55: =N55 -> 10530.2 | T55: =B55 -> 12412.95 | U55: =S55/T55-1 -> -0.15167627
A56: Hobart | B56: 12789.9 | C56: 9290 | D56: 10594.25 | E56: 10825.9 | F56: 12465.95 | G56: 10593.6 | H56: 9088.1 | I56: 12460.05 | J56: 12055.3 | K56: 11796.25 | L56: 12436.45 | M56: 10033.05 | N56: 10325.45 | R56: =A56 -> Hobart | S56: =N56 -> 10325.45 | T56: =B56 -> 12789.9 | U56: =S56/T56-1 -> -0.1926872
... A59: Sunshine Coast | B59: 11653.1 | C59: 8554.5 | D59: 10719.05 | E59: 11704.85 | F59: 11707.8 | G59: 11599.05 | H59: 11133.7 | I59: 10950.45 | J59: 12212.05 | K59: 11840 | L59: 11779.65 | M59: 8517.9 | N59: 10040.4 | R59: =A59 -> Sunshine Coast | S59: =N59 -> 10040.4 | T59: =B59 -> 11653.1 | U59: =S59/T59-1 -> -0.13839236
M89: 1
A90: Row Labels | B90: Sum of Quantity | E90: Row Labels | F90: Sum of Quantity | J90: Sum of Quantity | M90: =IF(M89=1,"Top","Bottom") -> Top | O90: Product | P90: Quantity
A91: Donuts in a box | B91: 20047 | E91: Sprite | F91: 11999 | J91: 482896 | O91: =IF(top.or.bottom="top",A91,E91) -> Donuts in a box | P91: =IF(top.or.bottom="top",B91,F91) -> 20047
A92: I can't believe this is cake | B92: 19975 | E92: Coke | F92: 12348 | O92: =IF(top.or.bottom="top",A92,E92) -> I can't believe this is cake | P92: =IF(top.or.bottom="top",B92,F92) -> 19975
A93: Cake in a cup | B93: 19833 | E93: Chewy Cashews | F93: 12631 | O93: =IF(top.or.bottom="top",A93,E93) -> Cake in a cup | P93: =IF(top.or.bottom="top",B93,F93) -> 19833
A94: Wall nuts | B94: 19748 | E94: Fanta | F94: 12742 | O94: =IF(top.or.bottom="top",A94,E94) -> Wall nuts | P94: =IF(top.or.bottom="top",B94,F94) -> 19748
A95: Lotta' Pie | B95: 19745 | E95: Fried Frozen Bananas | F95: 12777 | O95: =IF(top.or.bottom="top",A95,E95) -> Lotta' Pie | P95: =IF(top.or.bottom="top",B95,F95) -> 19745
O96: Rest of them | P96: =J91-SUM(P91:P95) -> 383548
O97: Pct of quantity | P97: =SUM(P91:P95)/J91 -> 0.20573374
...

Sheet Dashboard
C1: Business Dashboard | P1: =Pivot!I8 -> May-2018 | S1: Filters
C3: Key Trends & Variance
C5: Amount | G5: =Pivot!J1 -> Quantity | K5: =Pivot!K1 -> Orders | O5: =Pivot!L1 -> Customers
B6: =Pivot!I8 -> May-2018 | C6: =Pivot!I2 -> 81789.35 | D6: =Pivot!I4 -> -0.036302431 | G6: =Pivot!J2 -> 17247 | H6: =Pivot!J4 -> -0.062510192 | K6: =Pivot!K2 -> 2087 | L6: =Pivot!K4 -> -0.027039627 | O6: =Pivot!L2 -> 345 | P6: =Pivot!L4 -> 0
B7: =Pivot!I9 -> May-2017 | C7: =Pivot!I3 -> 84870.35 | G7: =Pivot!J3 -> 18397 | K7: =Pivot!K3 -> 2145 | O7: =Pivot!L3 -> 345
B8: Trend
C11: Store Performance | I11: Product Performance | M11: Customer Demographics
C13: =Pivot!R44 -> Store | D13: =Pivot!S44 -> Now | F13: =Pivot!U44 -> % Var | G13: Trend
C14: =Pivot!R45 -> Ballarat | D14: =Pivot!S45 -> 13829.4 | F14: =Pivot!U45 -> -0.013077469 | I14: =Pivot!P100 -> Top 5 Products
C15: =Pivot!R46 -> Geelong | D15: =Pivot!S46 -> 13314 | F15: =Pivot!U46 -> 0.39817693
C16: =Pivot!R47 -> Bendigo | D16: =Pivot!S47 -> 13249.5 | F16: =Pivot!U47 -> 0.22773773 | I16: =Pivot!P101 -> Make up 21% of sales.
C17: =Pivot!R48 -> Mackay | D17: =Pivot!S48 -> 11588.95 | F17: =Pivot!U48 -> -0.076419466
C18: =Pivot!R49 -> Cairns | D18: =Pivot!S49 -> 11284.45 | F18: =Pivot!U49 -> -0.14676572
C19: =Pivot!R50 -> Townsville | D19: =Pivot!S50 -> 11233.65 | F19: =Pivot!U50 -> -0.006021218
C20: =Pivot!R51 -> Gold Coast | D20: =Pivot!S51 -> 11135.3 | F20: =Pivot!U51 -> 0.21157027
C21: =Pivot!R52 -> Newcastle | D21: =Pivot!S52 -> 10860.8 | F21: =Pivot!U52 -> -0.1009532
C22: =Pivot!R53 -> Wollongong | D22: =Pivot!S53 -> 10736.85 | F22: =Pivot!U53 -> -0.12813444
C23: =Pivot!R54 -> Rockhampton | D23: =Pivot!S54 -> 10687 | F23: =Pivot!U54 -> -0.27380338
C24: =Pivot!R55 -> Central Coast | D24: =Pivot!S55 -> 10530.2 | F24: =Pivot!U55 -> -0.15167627
C25: =Pivot!R56 -> Hobart | D25: =Pivot!S56 -> 10325.45 | F25: =Pivot!U56 -> -0.1926872
C26: =Pivot!R57 -> Darwin | D26: =Pivot!S57 -> 10279.9 | F26: =Pivot!U57 -> -0.19080755
C27: =Pivot!R58 -> Canberra | D27: =Pivot!S58 -> 10162.35 | F27: =Pivot!U58 -> -0.069403173
C28: =Pivot!R59 -> Sunshine Coast | D28: =Pivot!S59 -> 10040.4 | F28: =Pivot!U59 -> -0.13839236
